Workbook

Sheet スケジュール（5日）
B2: ="コースプラン/インストラクションガイド 「"&master!$B$1&"_IG」" -> コースプラン/インストラクションガイド 「AI Native-提案演習_IG」
B4: 科目修了条件
B7: スケジュール
C9: 1 日目 | E9: 2 日目 | G9: 3 日目 | I9: 4 日目 | K9: 5 日目
A10: 0.39583333 | B10: 0.39583333 | C10: オリエンテーション | D10: 0.39583333 | E10: オリエンテーション | F10: 0.39583333 | G10: オリエンテーション | H10: 0.39583333 | I10: オリエンテーション | J10: 0.39583333 | K10: オリエンテーション
B11: 0.40625 | C11: =master!B4 -> 導入 | D11: 0.40625 | F11: 0.40625 | G11: =master!B39 -> チーム演習 | H11: 0.40625 | J11: 0.40625 | K11: =master!B48 -> 発表会（ブロック代表の決定）
A12: 0.41666667 | B12: 0.41666667 | C12: =master!B5 -> 企画提案のステップ
C13: =master!B16 -> まとめ
B14: 0.4375 | C14: =master!B18 -> 提案書サンプル
A16: 0.45833333 | B16: 0.45833333 | C16: =master!B31 -> 個人演習
A20: 0.5
B22: 0.52083333 | C22: お昼休み | D22: 0.52083333 | E22: お昼休み | F22: 0.52083333 | G22: お昼休み | H22: 0.52083333 | I22: お昼休み | J22: 0.52083333 | K22: お昼休み
A24: 0.54166667
B26: 0.5625 | D26: 0.5625 | F26: 0.5625 | H26: 0.5625 | J26: 0.5625 | K26: =master!B51 -> 発表会（最終）
A28: 0.58333333
A32: 0.625
A36: 0.66666667
A40: 0.70833333
B43: 0.73958333 | C43: 予備 | D43: 0.73958333 | E43: 予備 | F43: 0.73958333 | G43: 予備 | H43: 0.73958333 | I43: 予備 | J43: 0.73958333 | K43: 予備

Sheet 特記イベント
B2: 特記イベント
B4: 講師の事前準備
B7: 番号 | D7: 講師用資料の保存先 | F7: 配布タイミング | G7: 配布形式
B8: 共通1 | C8: オリエンテーション用資材 | D8: － | F8: 不要 | G8: 電子
C11: テーマ | D11: 主なポイント | G11: 使用教材 | H11: 環境 | I11: 共通 | K11: 実施上のの注意点
I12: 可否 | J12: 時間
C13: オリエンテーション | D13: ・教材のダウンロード ・本科目の概要説明 科目の位置づけや目的、全体スケジュールの説明 | G13: ・共通1 | I13: ○ | J13: 0.010416667

Sheet 講義
B2: 講義
B4: 講師の事前準備
B8: 番号 | C8: 使用教材 | D8: 研修ファイルサーバの保存先 | F8: 配布タイミング | G8: 配布形式
B9: AI-01 | C9: 【AI Native提案企画研修】研修にあたって.pptx | D9: － | F9: 済 | G9: 電子
B10: AI-02 | C10: 【AI Native提案企画研修】提案書サンプル.pptx | D10: － | F10: 済 | G10: 電子
B11: AI-03 | C11: 【AI Native提案企画研修】個人演習説明.pptx | D11: － | F11: 済 | G11: 電子
B12: AI-04 | C12: 【AI Native提案企画研修】チーム演習説明.pptx | D12: － | F12: 済 | G12: 電子
B14: 章 | C14: テーマ | D14: 主なポイント | G14: 使用教材 | H14: 環境 | I14: 共通 | K14: 実施上の注意点
I15: 可否 | J15: 時間
B16: =master!B4 -> 導入 | C16: =master!C4 -> はじめに ｜ “Be a social designer”とは | D16: NTTデータ デジタルソサエティ事業部が掲げる理念であり、ITやデジタル技術を活用して社会課題の解決に貢献し、より良い社会を創り出すことを意味する。 利用者である国民の目線を重視しながら、行政サービスの利便性向上やデジタル化を推進することで、誰一人取り残さない社会の実現を目指している。 | G16: ・AI-01 | I16: ○ | J16: 0.0020833333
B17: =master!B5 -> 企画提案のステップ | C17: =master!C5 -> 企画提案のステップ | D17: 以下の手順で提案演習を実施することを説明する。 ・STEP① アイデアの創出 ・STEP② 調査・確認 ・STEP③ 企画提案書・プロトタイプの作成 | G17: ・AI-01 | I17: ○ | J17: 0.0020833333
C18: =master!C6 -> STEP①-1 日常の不便を考える | D18: まずは「日常の不便」を出発点にすることで、現実的で価値のある改善アイデアにつながることを説明する。 ※注意点 自分だけの不便を起点にすると視野が狭くなりやすいため、そのままではサービスとしての価値が限定されてしまいます。 そこで、段階的に視点を広げることで、社会的な意味のある課題へと発展させます。 ① 自分の不便（起点） ② 他の人も同じか？（共通性の確認） ③ どの層に共通するか？（対象の整理・分類） ④ 社会課題として成立するか？（抽象化・構造化） このように段階的に拡張することで、単なる個人の体験ではなく、サービスや仕組みとして解決すべき社会課題として捉えることができる。 | G18: ・AI-01 | I18: ○ | J18: 0.0034722222
C19: =master!C7 -> STEP①-2 課題の深掘り | D19: 表面的な問題で止めず、「なぜそれが起きているのか？」を繰り返し問いかけることで、根本的な原因を探ることを説明する。 | G19: ・AI-01 | I19: ○ | J19: 0.0013888889
C20: =master!C8 -> STEP①-3 ITアイデアへ落とし込む | D20: 深掘りした課題をもとに、「どのように解決できるか」を考え、最終的に「ITアイデアへと変換」することを説明する。 以下の順番で整理することが重要である。 1. 誰が困っているのか（対象ユーザーの明確化） 2. 何が不便なのか（具体的な課題の整理） 3. どういう状態が理想なのか（ゴールの設定） 4. ITでどのように支援できるか（手段の検討） 【よくある間違い】 × 最初から「アプリを作ろう」「システム化しよう」と発想してしまう（ITありきの発想） → まずは課題解決を優先し、その手段として必要であればITを活用することが重要である。 | G20: ・AI-01 | I20: ○ | J20: 0.0020833333
C21: =master!C9 -> STEP②-1 創出したアイデアに関する調査・確認 | D21: 1. 既存事例・類似事例の有無 思いついたアイデアは、すでに世の中で実現されている可能性があるため、ネット検索や生成AIを活用して類似事例を調査する。 ※類似事例がある場合、むしろ「なぜ普及していないのか」「どこに改善余地があるのか」を分析することで、よりオリジナリティのあるアイデアにつなげる。 2. 実現可能性 どれだけ優れたアイデアであっても、実現できなければ意味がない。 技術的に可能か、コスト的に現実的かといった観点から、実装可能性を検討する。 3. ビジネスとしての成立性 サービスとして継続するためには収益性が必要である。 開発・運用コストに対して、どのように収益を得るのか（課金モデル・広告・BtoBなど）を整理し、ビジネスとして成立するかを検討する。 4. 社会への影響 “Be a social designer”の視点として、社会全体への影響を考慮する。 デジタル弱者への配慮、地域格差への影響、雇用への影響など、社会に対してプラスの効果を生み出せるかを確認する。 | G21: ・AI-01 | I21: ○ | J21: 0
C22: =master!C10 -> STEP②-2 環境分析 | D22: 提案を行うにあたっては、アイデアそのものだけでなく、企業を取り巻く外部環境や、自社の強み・弱みを理解することが重要である。 これにより、提案の実現性や説得力が高まり、より効果的なアイデア設計につながる。 ・外部環境分析 PEST分析 3C分析 ・内部環境分析 SWOT分析 | G22: ・AI-01 | I22: ○ | J22: 0.0020833333
C23: =master!C11 -> （参考）PEST分析 | D23: PEST分析は、企業を取り巻く「社会の変化」を4つの観点から整理するフレームワークである。 政治・経済・社会・技術といった、自社ではコントロールできない外部環境（マクロ環境）を把握することを目的としている。 これにより、今後の事業環境の変化や機会・リスクを整理することができる。 | G23: ・AI-01 | I23: ○ | J23: 0.0013888889
C24: =master!C12 -> （参考） 3C分析 | D24: 3C分析は、企業を取り巻く関係者を「顧客（Customer）」「競合（Competitor）」「自社（Company）」の3つの視点で整理するフレームワークである。 市場や環境を多面的に捉えることで、「誰のどんな課題を、自社のどの強みで解決できるか」を明確にすることを目的としている。 | G24: ・AI-01 | I24: ○ | J24: 0.0013888889
C25: =master!C13 -> （参考） SWOT分析 | D25: SWOT分析は、企業の現状を「強み（Strength）」「弱み（Weakness）」「機会（Opportunity）」「脅威（Threat）」の4つの視点で整理するフレームワークである。 内部環境と外部環境をあわせて整理することで、自社の強みをどのように活かし、変化や課題にどう対応するかを考えることを目的としている。 | G25: ・AI-01 | I25: ○ | J25: 0.0013888889
C26: =master!C14 -> STEP③-1 提案書作成 | D26: 提案書の必須要素を説明する。 ・対象とする企業（対象企業があれば） ・提案内容 ・提供する価値（顧客・社会へ提供する価値） ・社会への影響（NTT DATAとしてやる意義があるか） ・実現性・コスト・収益（事業として成立するか） ・市場・競合分析（チャンスがあるか） | G26: ・AI-01 | I26: ○ | J26: 0.0013888889
C27: =master!C15 -> STEP③-2 プロトタイプ作成 | D27: プロトタイプの目的を説明する。 実際の利用イメージやユーザー体験を可視化するために、プロトタイプを作成する。 プロトタイプとは、完成したシステムではなく「サービス体験を検証するための試作品」であり、「このサービスがあったらどのような体験になるのか」を具体的に伝えるためのモックである。 ※なお本プロトタイプは、生成AIを活用して作成することを前提とする | G27: ・AI-01 | I27: ○ | J27: 0.0013888889
B28: =master!B16 -> まとめ | C28: =master!C16 -> まとめ | D28: 以下の内容を説明する。 IT人材に求められるのは、単なる技術知識だけではない。 実際の業務では、課題発見力・多面的な視点・社会への理解・利用者視点といった能力が強く求められる。 本研修を通じて重要なのは、「技術をどう使うか」ではなく、「誰のどんな課題を、どのような価値に変えるのか」という視点である。 その結果として、社会に新たな体験や価値を生み出すことができるIT人材を目指してほしい。 | G28: ・AI-01 | I28: ○ | J28: 0.0013888889
B29: =master!B18 -> 提案書サンプル | C29: =master!C18 -> １．サマリ | D29: 提案内容と提案先企業が記載されていることを説明する。 | G29: ・AI-02 | I29: ○ | J29: 0.00069444444
C30: =master!C19 -> ２．背景 | D30: 背景（Why＝なぜ？）を説明する。 | G30: ・AI-02 | I30: ○ | J30: 0.0013888889
C31: =master!C20 -> ３．現状課題 | D31: 現状課題（What＝具体的なこまりごと）を説明する。 | G31: ・AI-02 | I31: ○ | J31: 0.0013888889
C32: =master!C21 -> ４．業界動向・市場分析 | D32: 周囲の環境変化や市場の動きがどのように影響するかを分析していることを説明する。 ・社会動向：社会全体で起きている大きな変化 ・業界動向：対象となる業界内で起きている変化 ・競合他社動向：同じ領域でサービスを提供している企業の動き | G32: ・AI-02 | I32: ○ | J32: 0.0013888889
C33: =master!C22 -> ５．市場機会 | D33: 市場機会について説明する。 3C分析により、顧客ニーズ・競合状況・自社の強みを整理し、市場機会（まだ十分に満たされていないニーズが存在し、価値提供できる可能性がある領域）を明らかにしている。 | G33: ・AI-02 | I33: ○ | J33: 0.0013888889
C34: =master!C23 -> ６．サービス概要 | D34: 現状課題を解決するためのサービス概要（サービスの全体像）を説明する。 ※利用者目線のみ | G34: ・AI-02 | I34: ○ | J34: 0.0013888889
C35: =master!C24 -> ７．利用者体験イメージ | D35: サービスの利用者体験イメージを説明する。 ペルソナ：サービスを使う代表的なユーザー像を具体的に作ったもの ストーリーボード：ユーザーがサービスを使う流れを物語（ストーリー）形式で描いたもの | G35: ・AI-02 | I35: ○ | J35: 0.0013888889
C36: =master!C25 -> ８．事業構成 | D36: サービスの事業構成（どういう要素で成り立たせるか：仕組み・構造）を説明する。 | G36: ・AI-02 | I36: ○ | J36: 0.0013888889
C37: =master!C26 -> ９．提供価値 | D37: サービスの提供価値について説明する。 ※Before / After フレームを利用するとわかりやすい。 | G37: ・AI-02 | I37: ○ | J37: 0.0013888889
C38: =master!C27 -> １０．収益モデル | D38: 収益モデル（そのサービスでどうやってお金を得て継続するか）について説明する。 ・誰からお金を得るか（課金対象） ・何に対してお金をもらうか（課金ポイント） ・どういう仕組みで継続収益になるか | G38: ・AI-02 | I38: ○ | J38: 0.0013888889
C39: =master!C28 -> １１．リスク・課題 | D39: リスクと課題について説明する。 リスク：うまくいかない可能性・障害要因 課題：解決すべき問題そのもの 対策：課題に対する、解決策 | G39: ・AI-02 | I39: ○ | J39: 0.0013888889
C40: =master!C29 -> １２．今後の展望 | D40: サービスの今後の展望について説明する。 | G40: ・AI-02 | I40: ○ | J40: 0.00069444444
B41: =master!B31 -> 個人演習 | C41: =master!C31 -> 演習内容の説明 | D41: 個人演習の概要について説明する。 ■手順 1. サービスの検討 2. サービスをチーム内でブラッシュアップ 3. サービスの決定 4. 成果物の作成 5. 成果物の提出 | G41: ・AI-03 | I41: ○ | J41: 0.0013888889
C42: =master!C32 -> 演習成果物の説明 | D42: 成果物の概要について説明する。 ■成果物の種類 ・企画提案書 PowerPoint形式で作成すること ・プロトタイプ 作成したアプリケーションのソースコード一式を提出すること ルートディレクトリをそのままzip化して提出すること ・命名規約 企画提案書 → 受講者ID_氏名_企画提案書.pptx プロトタイプ → 受講者ID_氏名_プロトタイプ.zip ■提出方法 ・提出方法：Teamの共有フォルダに格納してください。 ・提出先：全体連絡・共通＞02_AIネイティブ提案企画研修＞03_提出先＞01_個人演習 | G42: ・AI-03 | I42: ○ | J42: 0.0013888889
C43: =master!C33 -> サービスの検討 | D43: 解決したい課題やターゲットユーザーを明確にし、サービス案を検討することを説明する。 なお、サービス案の検討にあたっては、以下の観点を考慮すること。 ・提供する価値（顧客や社会にどのような価値を提供できるか） ・社会への影響（NTT DATAとして取り組む意義があるか） ・実現性・コスト・収益性（事業として成立するか） ・市場・競合分析（市場機会があり、競争優位性を確保できるか） 【生成AI利用ルール】 ・サービスの初期アイデア創出は、生成AIを利用せず自身で考えること。 ・サービス案が作成できた後は、アイデアの検証、調査、市場分析、競合分析、ブラッシュアップを目的として生成AIを利用してよい。 ・生成AIから得た情報は鵜呑みにせず、必要に応じて根拠や情報源を確認すること。 | G43: ・AI-03 | I43: ○ | J43: 0.013888889
C44: =master!C34 -> サービスのブラッシュアップ | D44: サービス案をチーム内で発表し、メンバーからフィードバックを受けることを説明する。 フィードバックでは、以下の観点を中心に意見交換を行うこと。 ・提供する価値が明確か ・解決したい課題やターゲットユーザーが適切か ・社会への影響や意義があるか ・実現性や事業性に課題はないか ・市場や競合との差別化ができているか フィードバックを踏まえ、サービス案をブラッシュアップする。 | G44: ・AI-03 | I44: ○ | J44: 0.020833333
C45: =master!C35 -> サービスの決定 | D45: チームメンバーからのフィードバックを踏まえ、サービス案をブラッシュアップすることを説明する。 フィードバック内容を整理し、必要に応じて課題設定、ターゲットユーザー、提供価値、機能案などを見直すこと。 ブラッシュアップ後、最終的に提案するサービスを決定する。 | G45: ・AI-03 | I45: ○ | J45: 0.020833333
C46: =master!C36 -> 成果物の作成 | D46: 決定したサービスについて、企画提案書およびプロトタイプを作成することを説明する。 ■企画提案書 解決したい課題、ターゲットユーザー、提供価値、社会的意義、実現性、市場性などを整理し、サービスの概要をまとめること。 ■プロトタイプ サービスの利用イメージや主要な画面を作成し、ユーザー体験を具体的に表現すること。 なお、本演習では実装の完成度ではなく、体験設計を重視する。分かりやすさ、使いやすさ、課題への理解、アイデアの納得感が伝わるように作成すること。 | G46: ・AI-03 | I46: ○ | J46: ー
...

Sheet master
B1: AI Native-提案演習
B2: 章の名称 | C2: 節の名称
B4: 導入 | C4: はじめに ｜ “Be a social designer”とは
B5: 企画提案のステップ | C5: 企画提案のステップ
C6: STEP①-1 日常の不便を考える
C7: STEP①-2 課題の深掘り
C8: STEP①-3 ITアイデアへ落とし込む
C9: STEP②-1 創出したアイデアに関する調査・確認
C10: STEP②-2 環境分析
C11: （参考）PEST分析
C12: （参考） 3C分析
C13: （参考） SWOT分析
C14: STEP③-1 提案書作成
C15: STEP③-2 プロトタイプ作成
B16: まとめ | C16: まとめ
B18: 提案書サンプル | C18: １．サマリ
C19: ２．背景
C20: ３．現状課題
C21: ４．業界動向・市場分析
C22: ５．市場機会
C23: ６．サービス概要
C24: ７．利用者体験イメージ
C25: ８．事業構成
C26: ９．提供価値
C27: １０．収益モデル
C28: １１．リスク・課題
C29: １２．今後の展望
B31: 個人演習 | C31: 演習内容の説明
C32: 演習成果物の説明
C33: サービスの検討
C34: サービスのブラッシュアップ
C35: サービスの決定
C36: 成果物の作成
C37: 成果物の提出
B39: チーム演習 | C39: 演習内容の説明
C40: 演習成果物の説明
C41: 【参考】最終発表時の評価基準
C42: サービスの提案
C43: サービスの決定（チーム）
C44: 成果物の作成
...
