Workbook

Sheet スケジュール（1日）
B2: ="コースプラン/インストラクションガイド 「"&master!B1&"_IG」" -> コースプラン/インストラクションガイド 「AI Native-生成AI_IG」
B4: 科目修了条件
B7: スケジュール
C9: 1 日目
A10: 0.39583333 | B10: 0.39583333 | C10: オリエンテーション | G10: ｐ
B11: 0.40625 | C11: =master!B3 -> 自己紹介
A12: 0.41666667 | B12: 0.41666667 | C12: =master!B5 -> 環境確認 | G12: ｐ
B14: 0.4375 | C14: =master!B6 -> 01. オリエンテーションとマインドセット変革
B15: 0.44791667 | C15: =master!B9 -> 02. AI・LLMの基礎理解
A16: 0.45833333 | B16: 0.45833333 | C16: =master!B14 -> 03. NTTデータが目指すAIビジネス（Vision）
B19: 0.48958333 | C19: =master!B29 -> 04. プロンプトエンジニアリング
A20: 0.5
B21: 0.51041667 | C21: 予備
B22: 0.52083333 | C22: お昼休み
A24: 0.54166667
B26: 0.5625 | C26: =master!B36 -> 05. ハンズオン（ChatGPT）
A28: 0.58333333
B30: 0.60416667 | C30: =master!B46 -> 06. ハンズオン（ GitHub Copilot ）
A32: 0.625
A36: 0.66666667
A40: 0.70833333
B41: 0.71875 | C41: =master!B75 -> 成果物のプレゼン
B43: 0.73958333 | C43: 予備 | G43: ｐ

Sheet 特記イベント
B2: 特記イベント
B4: 講師の事前準備
B7: 番号 | C7: 使用教材 | D7: 講師用資料の保存先 | F7: 配布タイミング | G7: 配布形式
B8: 共通1 | C8: 【AI Native研修-生成AI】研修の概要.pptx | D8: － | F8: 不要 | G8: 電子
C10: テーマ | D10: 主なポイント | G10: 使用教材 | H10: 環境 | I10: 共通 | K10: 実施上のの注意点
I11: 可否 | J11: 時間
C12: オリエンテーション | D12: ・教材のダウンロード ・本科目の概要説明 科目の位置づけや目的、全体の説明 | G12: ・共通1 | I12: ○ | J12: 0.010416667

Sheet 講義
B2: 講義
B4: 講師の事前準備
B5: 特になし
B7: 番号 | C7: 使用教材 | D7: 講師用資料の保存先 | F7: 配布タイミング | G7: 配布形式
B8: AI-01 | C8: 【AI Native研修】 生成AIの基礎.pptx | D8: － | F8: 済 | G8: 電子
B10: 章 | C10: テーマ | D10: 主なポイント | G10: 使用教材 | H10: 環境 | I10: 共通 | K10: 実施上の注意点
I11: 可否 | J11: 時間
B12: =master!B3 -> 自己紹介 | C12: =master!C3 -> 講師の自己紹介 | D12: 以下の内容を実施する。 ■講師による自己紹介 (3分) ・氏名 ・経歴 ・その他 | I12: ○ | J12: 0.0034722222
C13: =master!C4 -> 受講生の自己紹介 | D13: 以下の内容を実施してもらう。 ■グループ内での自己紹介（2分*人数） ・氏名 ・部署 ・その他 | I13: ○ | J13: 0.0069444444
B14: =master!B5 -> 環境確認 | C14: =master!C5 -> 研修環境の確認 | D14: 以下の内容を実施してもらう。 ■以下を実施し、問題がないかを確認する。 ・ChatGPTのログイン ・環境へのログイン ・VS Codeの起動 ・GitHub Copilotへのログイン 受講生は各自のメールアドレスでGitHubにログインするため、複数の組織が表示さる可能性があります。 必ず、研修用の組織を選択するようにアナウンスをお願いします。 組織を間違えると、研修で必要なGitHub Copilotを利用できない場合があります。 | I14: ○ | J14: 0.013888889
B15: =master!B6 -> 01. オリエンテーションとマインドセット変革 | C15: =master!C6 -> 1-1. 研修概要 | D15: 以下の内容を伝える。 ■研修の内容 ・生成AIと協働しながら業務を自走する力を養い、AI時代の基盤となる人材を育成する研修 ■実施構成 バイブコーディングフェーズ 企画提案フェーズ ■各フェーズの概要の説明 バイブコーディングフェーズ⇒生成AIを活用し、Java AP開発・単体テストをAIと実践する 企画提案フェーズ⇒生成AIを活用し、企画・モック・提案・改善をチームで実践する | G15: ・AI-01 | I15: ○ | J15: 0.0013888889
C16: =master!C7 -> 1-2. 背景・目的 | D16: 以下の内容を伝える。 ■背景 ・生成AIの進化により、AIと協働する開発へと変化しており、今後はAIを活用した開発プロセスを設計・実践できる人財が必要となっている。 ■目的 ・生成AIを前提とした開発プロセスを理解・実践できる人財を育成し、将来的な業務プロセスの変革の基盤を構築する | G16: ・AI-01 | I16: ○ | J16: 0.0013888889
C17: =master!C8 -> 1-3. 研修ゴールと獲得可能な経験背景・目的 | D17: 以下の内容を伝える。 ■研修ゴール ・生成AIを活用して成果物を作成できる ・AIとの試行錯誤により成果物の品質を高めることができる ・AIを活用した開発の進め方を理解できるようになる_x000B_ ・AIを活用した企画・提案の進め方を理解できるようになる ・AI時代の働き方の基礎を習得できる ■獲得可能な経験 ・ ChatGPT を用いた 「調査・整理」、「叩き台資料作成」、「モックアプリ開発」、「企画・提案書骨子作成」、「成果物RV」の経験 ・ GitHub Copilot を用いた AIエージェント への作業指示および上述の成果物作成・修正・RVの経験 ・ GitHub Copilot を用いる際の 各種ハーネスエンジニアリング に向けたAI動作環境の改善経験 ・ 生産性向上および品質向上を実現するための開発プロセスの改善経験 ■目標 ・高度な自走ではなく、生成AIを活用して実務に取り組めるレベルへの到達 | G17: ・AI-01 | I17: ○ | J17: 0.0020833333
B18: =master!B9 -> 02. AI・LLMの基礎理解 | C18: =master!C9 -> 2-1. 生成AI（Generative AI）とは？ | D18: 以下の内容を伝える。 ■生成AIとは ・自らデータを「生成」するAIのこと 学習した膨大なデータをもとに、テキスト、画像、音声などを新しく生み出す ・自然言語インターフェース 人間が普段使っている言葉（日本語や英語）で指示を出すだけで、高度な処理を実行できる ■AI時代の働き方の変化 ・人間が手を動かす時代から、AIにどう指示を出すかを考える時代へ変化している。 | G18: ・AI-01 | I18: ○ | J18: 0.0013888889
C19: =master!C10 -> 2-2. 従来型AIと生成AIの比較 | D19: 以下の内容を伝える。 ■従来のAI（識別型AI） ・目的：データの分類・予測 ・特徴：判断するAIであり、すでにあるデータを見て「これは何か？」を答える。 ■生成AI（Generative AI） ・目的：新しいコンテンツの創造 ・特徴：作り出すAIであり、文章・画像・音声など、人間が作るような新しいコンテンツを生み出す。 | G19: ・AI-01 | I19: ○ | J19: 0.0013888889
C20: =master!C11 -> 2-3. LLM（大規模言語モデル）の仕組み | D20: 以下の内容を伝える。 ■LLMとは ・ChatGPTやCopilotの頭脳にあたる部分 ■特徴 ・高度な次単語予測 文脈の次に続く最も確率の高い単語を計算し続けている。 ※なぜ精度が高いのか？ インターネット上の膨大なテキストデータを学習しているため、極めて精度の高い予測が可能になる。 | G20: ・AI-01 | I20: ○ | J20: 0.0020833333
C21: =master!C12 -> 2-4. 生成AIの「苦手なこと」（弱み） | D21: 以下の内容を伝える。 ■情報の「正確性」の担保（情報の正確性） ・もっともらしい誤情報（ハルシネーション）を生成することがあるため、最終的な確認・判断は人間が行う。 ■高度に専門的・クローズドな知識（専門的・社内固有の知識） ・自社独自のルールや、AIが知らない最新・専門的な情報には、正しく回答できない場合がある。 ■「暗黙の了解」の理解（暗黙の了解） ・言葉にされていない背景や意図を正確に理解できないため、前提条件や目的を具体的に伝える必要がある。 | G21: ・AI-01 | I21: ○ | J21: 0.0020833333
C22: =master!C13 -> 2-5. 生成AIを使う心得８条 | D22: 以下の内容を伝える。 ■AIを使う前に身につけるべきマインドセット ① AIを「0→100」で使おうとしない → AIに丸投げせず、たたき台作成や作業支援に活用する。 ② AIを「思考の下処理」として使う → 情報整理や論点整理を任せ、人は判断に集中する。 ③ LLMは物事を「理解しているわけではない」ことを理解する → AIは理解ではなく予測で文章を生成しているため、誤りを含む可能性がある。 ④ AIへの評価を1ヶ月以上固定化しない → AIは急速に進化するため、定期的に再評価する。 ⑤ AIは人間を代替するものではなく、エンパワーメント（拡張）するものとして捉える → AIは人を置き換えるのではなく、人の能力を拡張する道具である。 ⑥ 「本の表紙」ではなく「中身」を読む → 世間の評判だけで判断せず、自ら試して実力を見極める。 ⑦ 良いプロンプトとは即ち「部下への良い指示」であると知る → 明確な指示ほど、期待に近い成果物を得られる。 ⑧ ガイドラインや社内ルールを踏まえて活用する → セキュリティやコンプライアンスを守りながら利用する。 | G22: ・AI-01 | I22: ○ | J22: 0.0034722222
B23: =master!B14 -> 03. NTTデータが目指すAIビジネス（Vision） | C23: =master!C14 -> 3-1. 本モジュールで学ぶこと① | D23: 以下の内容を説明する。 ■本モジュールで学ぶこと ① NTTデータのAI戦略 ・NTTデータが「Quality Growth」を掲げ、AIをどのように事業の中核に据えているかを理解する。 ② 生成AIの進化とAgentic AI ・生成AIがチャットボットからエージェントへ進化する中で、何が変わるのかを理解する。 ③ NTTデータが描く未来と社員として知っておくべきこと ・NTTデータが描くAI活用の未来像と、その実現に向けて必要な考え方や事例を学ぶ。 | G23: ・AI-01 | I23: ○ | J23: 0.00069444444
C24: =master!C15 -> 3-2. NTTデータのAI戦略：Quality Growthとは | D24: 以下の内容を説明する。 ■Quality Growthとは ・「顧客への価値提供を最大化し、持続的な成長と両立する質を伴った成長」を目指す考え方である。 ■AI戦略 ・AIを全事業に組み込んだ「AI-empowered New Value & Productivity」を中核戦略としている。 | G24: ・AI-01 | I24: ○ | J24: 0.0020833333
C25: =master!C16 -> 3-3. なぜ今、AIが重要なのか | D25: 以下の内容を説明する。 ■AIが重要となる背景 ・生成AI活用による競争激化により、提供価値の劣後や価格競争が生じる可能性がある。 ・国内労働人口の減少により、人財確保やノウハウ継承が課題となっている。 ■求められる変革 ・AIによる変革を推進できる人財の拡充と、AIを前提としたシステム・データの整備が必要である。 ・競争領域では価値創造、非競争領域では効率化を進めることが重要である。 | G25: ・AI-01 | I25: ○ | J25: 0.0020833333
C26: =master!C17 -> 3-4. 生成AIの進化：今、どこにいるか | D26: 以下の内容を説明する。 ■生成AIの進化 ・現在はLevel1～2の段階であり、チャットボットや推論を中心に活用されている。 ・今後はLevel3のエージェントへ移行し、AIが自律的に業務を遂行する世界へ進化していく。 | G26: ・AI-01 | I26: ○ | J26: 0.0020833333
C27: =master!C18 -> 3-5. 本モジュールで学ぶこと② | D27: 以下の内容を説明する。 ■本モジュールで学ぶこと ・生成AIの進化とAgentic AIについて学ぶ。 ・Agentic AIが目標に基づいて計画・実行・評価・改善を行う仕組みを理解する。 | G27: ・AI-01 | I27: ○ | J27: 0.00069444444
C28: =master!C19 -> 3-6. エージェントAI（Agentic AI）とは何か | D28: 以下の内容を説明する。 ■AgenticAI ・AgenticAIとは、「目標を与えると、自ら計画を立て、必要な作業を実行しながら目的達成を目指すAI」のこと ※目標達成のためにPDCAを繰り返す。 | G28: ・AI-01 | I28: ○ | J28: 0.0013888889
C29: =master!C20 -> 3-7. エージェントの処理 | D29: 以下の内容を説明する。 ■AgenticAIにおけるエージェント内の処理の流れ（PDCAの詳細） 1. プロンプトを受け取る 2. PDCAサイクルを繰り返し、回答を作成する。 | G29: ・AI-01 | I29: ○ | J29: 0.0020833333
C30: =master!C21 -> 3-8. 本モジュールで学ぶこと③ | D30: 以下の内容を説明する。 ■本モジュールで学ぶこと ・NTTデータが描くAI活用の未来像を理解する。 ・Smart AI Agent®、AIを起点とした業務変革、人とAIの役割分担について学ぶ。 ・具体的な事例を通じて、AIによる価値創出の考え方を理解する。 | G30: ・AI-01 | I30: ○ | J30: 0.00069444444
C31: =master!C22 -> 3-9. NTTデータが描く未来：Smart AI Agent® | D31: 以下の内容を説明する。 ■Smart AI Agent®とは ・複数のAIエージェントが自律的に協働する構想である。 ・業務の抜本的変革によるP/Lインパクトの創出と、新たなビジネス価値の創造を目指している。 | G31: ・AI-01 | I31: ○ | J31: 0.0020833333
C32: =master!C23 -> 3-10. AIの強みを生かした業務変革の進め方 | D32: 以下の内容を説明する。 ■AIを起点とした業務変革 ・AIの強みや業務適用の発想を踏まえ、従来の考え方を転換することが重要である。 ・AIを起点として、顧客企業の変革を提言・実現する。 | G32: ・AI-01 | I32: ○ | J32: 0.0020833333
C33: =master!C24 -> 3-11. AIの強みを生かすポイント：人とAIとの役割分担 | D33: 以下の内容を説明する。 ■人とAIの役割分担 ・AIを前提に業務を再設計する際は、人とAIの役割分担を再定義する。 ・AIの強みを最大限に活用し、人間だけでは実現できない価値の創出を図る。 | G33: ・AI-01 | I33: ○ | J33: 0.0020833333
C34: =master!C25 -> 3-12. AIの強みを生かすポイント：プロセス自体をAI前提で再設計 | D34: 以下の内容を説明する。 ■AI前提のプロセス再設計 ・AIを補助的に利用して既存業務を効率化するだけではなく、プロセス自体をAI前提で再設計する。 ・業務全体を見直し、AIの活用効果を最大化することが重要である。 | G34: ・AI-01 | I34: ○ | J34: 0.0020833333
C35: =master!C26 -> 3-13. JALカード様 - AIバーチャル顧客を活用したマーケティング高度化 | D35: 以下の内容を説明する。 ■AIバーチャル顧客の活用事例 ・AIバーチャル顧客との会話から、JALカード会員への効果的なマーケティング施策を導出した事例である。 ■成果 ・AI上のグループインタビューから得た示唆をもとにターゲットを選定し、販促プロモーションの購買率が3.0％向上した。 | G35: ・AI-01 | I35: ○ | J35: 0.0034722222
... C37: =master!C28 -> Appendix：りそな様 - AI CoEと生成AI人財育成アカデミーの推進 | D37: 以下の内容を説明する。 ■AI CoEと生成AI人財育成の事例 ・りそなグループでは、NTTデータの支援のもと、AIドリブンの企画・推進組織「AI CoE」を設置している。 ・生成AI人財育成アカデミーを推進している。 | G37: ・AI-01 | I37: ○ | J37: 0.0034722222
B38: =master!B29 -> 04. プロンプトエンジニアリング | C38: =master!C29 -> 4-1. プロンプトとは? | D38: 以下の内容を説明する。 ■プロンプトとは ・プロンプト（Prompt）とは、生成AIに対して「何をしてほしいか」を伝える指示文のこと ■高品質な回答を引き出す鍵 ・「日本語でいかに論理的かつ具体的に要件を定義できるか（プロンプト力）」が重要である | G38: ・AI-01 | I38: ○ | J38: 0.0013888889
C39: =master!C30 -> 4-2. プロンプトを構成する4つの要素 | D39: 以下の内容を説明する。 ■プロンプトを構成する4つの要素 ・Role（役割）：AIに役割を与え、視点と専門性を定める。 ・Context（背景）：依頼の目的や対象者などの前提条件を共有する。 ・Task（指示）：実行してほしい具体的なアクションを明確にする。 ・Format（形式）：表形式、箇条書き、文字数などの出力形式を指定する。 | G39: ・AI-01 | I39: ○ | J39: 0.0013888889
C40: =master!C31 -> 4-3. 悪いプロンプト vs 良いプロンプト | D40: 以下の内容を説明する。 ■プロンプトによる回答品質の違い ・対象者、目的、条件、出力形式が不明確なプロンプトでは、期待する回答を得にくい。 ・役割、背景、具体的な指示、出力形式を明確にすることで、回答品質を高めることができる。 | G40: ・AI-01 | I40: ○ | J40: 0.0013888889
C41: =master!C32 -> 4-4. テクニック①：Role Prompting（役割の付与） | D41: 以下の内容を説明する。 ■Role Promptingとは ・AIに「プロのコンサルタント」や「新入社員のメンター」などの役割を与える手法である。 ■効果 ・期待する視点や専門性、トーンで回答を生成しやすくなる。 | G41: ・AI-01 | I41: ○ | J41: 0.0020833333
C42: =master!C33 -> 4-5. テクニック②：区切り文字の活用 | D42: 以下の内容を説明する。 ■区切り文字の活用 ・###、---、【指示】【データ】などを使い、指示文と参照データを明確に分離する。 ■効果 ・AIが命令と処理対象を認識しやすくなり、意図しない解釈やハルシネーションを減らすことができる。 | G42: ・AI-01 | I42: ○ | J42: 0.0020833333
C43: =master!C34 -> 4-6. テクニック③：Zero-shot vs Few-shot | D43: 以下の内容を説明する。 ■Zero-shot Prompting ・例示を与えず、AIへ直接タスクを指示する方法である。 ■Few-shot Prompting ・事前に入力と出力の例を提示する方法である。 ・出力形式を厳密に守らせたい場合に有効である。 | G43: ・AI-01 | I43: ○ | J43: 0.0020833333
C44: =master!C35 -> 4-7. テクニック④：Chain of Thought（思考の連鎖） | D44: 以下の内容を説明する。 ■Chain of Thought（思考の連鎖） ・複雑な問題や業務フローの設計において、考える順序やプロセスを分解して指示する手法である。 ■実践のポイント ・「まずAを考え、次にBを評価し、最後にCを出力する」のように、処理の流れを明確に指示する。 | G44: ・AI-01 | I44: ○ | J44: 0.0020833333
B45: =master!B36 -> 05. ハンズオン（ChatGPT） | C45: =master!C36 -> 5-1. ChatGPTの使い方（一般チャット） | D45: 以下の内容を説明する。 ■UIについて ・プロンプトの入力欄 ※NTTD専用のChatGPTであることを確認する。 | G45: ・AI-01 | I45: ○ | J45: 0.00069444444
...

Sheet master
B1: AI Native-生成AI
B2: 章の名称 | C2: 節の名称
B3: 自己紹介 | C3: 講師の自己紹介
C4: 受講生の自己紹介
B5: 環境確認 | C5: 研修環境の確認
B6: 01. オリエンテーションとマインドセット変革 | C6: 1-1. 研修概要
C7: 1-2. 背景・目的
C8: 1-3. 研修ゴールと獲得可能な経験背景・目的
B9: 02. AI・LLMの基礎理解 | C9: 2-1. 生成AI（Generative AI）とは？
C10: 2-2. 従来型AIと生成AIの比較
C11: 2-3. LLM（大規模言語モデル）の仕組み
C12: 2-4. 生成AIの「苦手なこと」（弱み）
C13: 2-5. 生成AIを使う心得８条
B14: 03. NTTデータが目指すAIビジネス（Vision） | C14: 3-1. 本モジュールで学ぶこと①
C15: 3-2. NTTデータのAI戦略：Quality Growthとは
C16: 3-3. なぜ今、AIが重要なのか
C17: 3-4. 生成AIの進化：今、どこにいるか
C18: 3-5. 本モジュールで学ぶこと②
C19: 3-6. エージェントAI（Agentic AI）とは何か
C20: 3-7. エージェントの処理
C21: 3-8. 本モジュールで学ぶこと③
C22: 3-9. NTTデータが描く未来：Smart AI Agent®
C23: 3-10. AIの強みを生かした業務変革の進め方
C24: 3-11. AIの強みを生かすポイント：人とAIとの役割分担
C25: 3-12. AIの強みを生かすポイント：プロセス自体をAI前提で再設計
C26: 3-13. JALカード様 - AIバーチャル顧客を活用したマーケティング高度化
... C28: Appendix：りそな様 - AI CoEと生成AI人財育成アカデミーの推進
B29: 04. プロンプトエンジニアリング | C29: 4-1. プロンプトとは?
C30: 4-2. プロンプトを構成する4つの要素
C31: 4-3. 悪いプロンプト vs 良いプロンプト
C32: 4-4. テクニック①：Role Prompting（役割の付与）
C33: 4-5. テクニック②：区切り文字の活用
C34: 4-6. テクニック③：Zero-shot vs Few-shot
C35: 4-7. テクニック④：Chain of Thought（思考の連鎖）
B36: 05. ハンズオン（ChatGPT） | C36: 5-1. ChatGPTの使い方（一般チャット）
C37: 5-2. 例①：顧客提案向けの企画提案書を作りたい
C38: 5-3. 例①：顧客提案向けの企画提案書を作りたい - プロンプト例
C39: 5-4. 例①：顧客提案向けの企画提案書を作りたい - 実行例
C40: 5-5. 例②：100本ノックを作ってみる
C41: 5-6. 例②：100本ノックを作ってみる -プロンプト例
...
