Workbook

Sheet スケジュール（3日）
B2: ="コースプラン/インストラクションガイド 「"&master!$B$1&"_IG」" -> コースプラン/インストラクションガイド 「AI Native-バイブコーディング_IG」
B4: 科目修了条件
B7: スケジュール
C9: 1 日目 | E9: 2 日目 | G9: 3 日目
A10: 0.39583333 | B10: 0.39583333 | C10: オリエンテーション | D10: 0.39583333 | E10: オリエンテーション | F10: 0.39583333 | G10: オリエンテーション
B11: 0.40625 | C11: =master!B3 -> バイブコーディングの導入 | D11: 0.40625 | E11: =master!B67 -> 課題1の実施 | F11: 0.40625 | G11: =master!B67 -> 課題1の実施
A12: 0.41666667 | C12: =master!B4 -> Webアプリケーションとは | G12: =master!B156 -> 課題2の実施
B13: 0.42708333 | C13: =master!B9 -> データベースとは
B15: 0.44791667 | C15: =master!B17 -> Java言語、Springフレームワークとは
A16: 0.45833333
A20: 0.5 | B20: 0.5 | C20: 予備
B22: 0.52083333 | C22: お昼休み | D22: 0.52083333 | E22: お昼休み | F22: 0.52083333 | G22: お昼休み
A24: 0.54166667
B26: 0.5625 | C26: =master!B37 -> 課題1の導入 | D26: 0.5625 | E26: =master!B116 -> 単体テストとJunitの導入 | F26: 0.5625
E27: =master!B119 -> テストとは
A28: 0.58333333 | B28: 0.58333333 | C28: =master!B40 -> Spring Bootプロジェクトの_x000B_準備、起動確認 | D28: 0.58333333 | E28: =master!B123 -> 単体テストとは
B30: 0.60416667 | C30: =master!B44 -> ECサイト Webアプリの要件
A32: 0.625 | B32: 0.625 | C32: =master!B53 -> ハンズオン
D34: 0.64583333 | E34: =master!B141 -> JUnit
D35: 0.65277778 | E35: =master!B144 -> 課題2の導入
A36: 0.66666667 | D36: 0.66666667 | E36: =master!B148 -> ハンズオン
B38: 0.6875 | C38: Git | F38: 0.6875 | G38: =master!B164 -> 演習の振り返り
A40: 0.70833333
B41: 0.71875 | C41: Git
F42: 0.72916667 | G42: 予備
B43: 0.73958333 | C43: 予備 | D43: 0.73958333 | E43: 予備

Sheet 特記イベント
B2: 特記イベント
B4: 講師の事前準備
B7: 番号 | C7: 使用教材 | D7: 講師用資料の保存先 | F7: 配布タイミング | G7: 配布形式
B8: 共通1 | C8: 【AI Native研修-バイブコーディング】研修の概要.pptx | D8: － | F8: 不要 | G8: 電子
C10: テーマ | D10: 主なポイント | G10: 使用教材 | H10: 環境 | I10: 共通 | K10: 実施上のの注意点
I11: 可否 | J11: 時間
C12: オリエンテーション（初日） | D12: ・教材のダウンロード ・本科目の概要説明 科目の位置づけや目的、全体の説明 | G12: ・共通1 | I12: ○ | J12: 0.010416667
C13: オリエンテーション（2日目以降） | D13: ・本日のスケジュールの説明 | G13: ・共通1 | I13: ○ | J13: 0.010416667

Sheet 講義
B2: 講義
B4: 講師の事前準備
B7: 番号 | C7: 使用教材 | D7: 講師用資料の保存先 | F7: 配布タイミング | G7: 配布形式
B8: AI-01 | C8: 【AI Native研修-バイブコーディング①】WebとDBとJavaとSpring.pptx | D8: － | F8: 済 | G8: 電子
B9: AI-02 | C9: 【AI Native研修-バイブコーディング②】システム開発プロセス.pptx | D9: － | F9: 済 | G9: 電子
B10: AI-03 | C10: 【AI Native研修-バイブコーディング③】単体テストとJUnit.pptx | D10: － | F10: 済 | G10: 電子
B11: AI-04 | C11: 【AI Native研修-バイブコーディング】演習課題1 JavaでECサイト APを作成.pptx | D11: － | F11: 済 | G11: 電子
B12: AI-05 | C12: 【AI Native研修-バイブコーディング】演習課題2 JUnitで単体テスト.pptx | D12: － | F12: 済 | G12: 電子
B13: AI-06 | C13: 【AI Native研修-バイブコーディング】GitHubCopilotのLLM選択についての説明.pptx | D13: － | F13: 済 | G13: 電子
B14: AI-07 | C14: 【AI Native研修-バイブコーディング】Git入門.docx | D14: － | F14: 済 | G14: 電子
B15: AI-08 | C15: 【AI Native研修-バイブコーディング】Git入門_演習.docx | D15: － | F15: 済 | G15: 電子
B16: AI-09 | C16: 【AI Native研修-バイブコーディング】AIレビュー演習手順書.pptx | D16: － | F16: 済 | G16: 電子
B17: AI-10 | C17: 【AI Native研修-バイブコーディング】演習振り返り.docx | F17: 済 | G17: 電子
B18: AI-11 | C18: ec-webapp-example.zip | D18: － | F18: 済 | G18: 電子
B20: 章 | C20: テーマ | D20: 主なポイント | G20: 使用教材 | H20: 環境 | I20: 共通 | K20: 実施上の注意点
I21: 可否 | J21: 時間
B22: =master!B3 -> バイブコーディングの導入 | C22: =master!C3 -> 講義の目的 | D22: 以下の内容を伝える。 これから以下の内容について説明します。 ・Webアプリケーションの概要を理解する ・Webアプリケーションを開発する技術の概要を理解する 講義を聞くだけでなく、生成AIも積極的に活用してください。 分からない用語や仕組み、関連技術について生成AIに質問しながら学習することで、より理解を深めることができます。 生成AIを「答えを教えてもらうためのツール」ではなく、「理解を支援してくれる学習パートナー」として活用しながら受講してください。 | G22: ・AI-01 | I22: ○ | J22: 0.0020833333
B23: =master!B4 -> Webアプリケーションとは | C23: =master!C4 -> Webアプリケーションとは | D23: 以下の内容を詳細に説明する。 ・クライアントとサーバー ・リクエストとレスポンス クライアント：サービスを利用する側（利用者の端末やアプリケーション） サーバー：サービスを提供する側（データや機能を管理するシステム） リクエスト：クライアントからサーバーへの依頼 レスポンス：サーバーからクライアントへの応答 ※AmazonなどのWebアプリケーションを例に挙げ、わかりやすさを重視した説明をしてください。 | G23: ・AI-01 | I23: ○ | J23: 0.0034722222
C24: =master!C5 -> Webアプリケーションの種類 | D24: 「Web画面アプリケーション」、「WebAPIアプリケーション」について、以下の観点を説明する。 ・利用者と利用方法 ・構成 ・レスポンス ・具体例 | G24: ・AI-01 | I24: ○ | J24: 0.0034722222
C25: =master!C6 -> アプリケーションとは | D25: 図を中心にアプリケーションとハードウェアとの関係を説明する。 アプリケーションとは、「特定の作業を行うために開発されたソフトウェアプログラム」のこと | G25: ・AI-01 | I25: ○ | J25: 0.0020833333
C26: =master!C7 -> Web画面アプリケーション | D26: 図を中心に以下の用語を説明する。 ・ブラウザ ・HTML ※ここではレスポンスの話が中心 | G26: ・AI-01 | I26: ○ | J26: 0.0020833333
D27: ブラウザのデバッガでレスポンスを確認するデモを見せる。 ※レスポンスボディのHTMLを確認する | G27: ・AI-01 | I27: ○ | J27: 0.00069444444
C28: =master!C8 -> ブラウザからのリクエスト種類 | D28: HTTPメソッドとは、「クライアントがサーバーに対して何をしたいのか」を表す種類のこと ・GET:データの取得が目的 ・POST：データの送信が目的 ・PUT：データの更新が目的 ・DELETE：データの削除が目的 ※データ構造の説明は不要です。 | G28: ・AI-01 | I28: ○ | J28: 0.0020833333
B29: =master!B9 -> データベースとは | C29: =master!C9 -> データベースとは | D29: データベースとは、「データベースとは、データを効率的に保存・管理し、検索や更新を容易に行うために整理された情報の集まり」のこと 本研修では、「リレーショナルデータベース」を利用することを伝える。 ※データベースの形態の表があるが分類の粒度が不適切なので、サラッとながす。 | G29: ・AI-01 | I29: ○ | J29: 0.0020833333
C30: =master!C10 -> リレーショナルデータベース | D30: 以下の概要を説明する。 ・テーブル：関連するデータを表形式でまとめたもの ・行：1件分のデータ（横方向） ・列：データの項目（縦方向） ・関係：テーブル同士のつながり ・SQL：テーブルを操作するための言語 | G30: ・AI-01 | I30: ○ | J30: 0.0034722222
C31: =master!C11 -> データベースの役割 | D31: データの管理が主体であることを説明する。 | G31: ・AI-01 | I31: ○ | J31: 0.0034722222 | K31: ※アニメーション
C32: =master!C12 -> 2.1.テーブル | D32: 以下の概要を説明する。 ・テーブル：Excelのシート ・レコード：Excelの行 ・カラム：Excelの列 ・フィールド：Excelのセル | G32: ・AI-01 | I32: ○ | J32: 0.0020833333
C33: =master!C13 -> 2.2.データ型１ | D33: データ型とは、「データの性質や範囲などを定義する制約」のこと データ型の種類 ・数値型 ・文字列型 ・日付型 ・バイナリデータ型 etc. | G33: ・AI-01 | I33: ○ | J33: 0.0020833333
C34: =master!C14 -> 2.2.データ型２ | D34: データベースの種類によって異なることを説明する。 ※今回はH2DBなので細かい説明は不要。 | G34: ・AI-01 | I34: ○ | J34: 0.0020833333
C35: =master!C15 -> 2.3.リレーション | D35: リレーション＝リレーションシップという意味として説明する。 リレーションとは、「テーブル同士の関連」のこと | G35: ・AI-01 | I35: ○ | J35: 0.0034722222
C36: =master!C16 -> 2.4.データを結合して取得（Join） | D36: 結合（JOIN）とは、「関連するデータを組み合わせて取得する」こと 例）赤、青 | G36: ・AI-01 | I36: ○ | J36: 0.0020833333
B37: =master!B17 -> Java言語、Springフレームワークとは | C37: =master!C17 -> Webアプリケーションを作成するためのプログラミング言語 | D37: Javaの選定理由を説明する。 ・言語自体の処理性能が優れており、大規模Webアプリケーション開発に適している ・NTTデータにおけるシステム開発で広く使われているため ・世界的に開発者数、使用数が多いため ※ナレッジが多い言語を使った方が生成AIとの相性が良い。 | G37: ・AI-01 | I37: ○ | J37: 0.0020833333
C38: =master!C18 -> Java | D38: 言語の特徴を説明する。 ・コンパイルが必要な言語 ・JVM（Java Virtual Machine） ・難しかったメモリ管理が不要 ・オブジェクト指向をもとにしたオブジェクト指向プログラミングをサポート | G38: ・AI-01 | I38: ○ | J38: 0.0034722222
C39: =master!C19 -> Java言語の構成要素 | D39: 各要素の関係が理解できるように説明する。 ・Jarファイル ・パッケージ ・クラス ・メソッド | G39: ・AI-01 | I39: ○ | J39: 0.0020833333
C40: =master!C20 -> Webアプリケーションを構成するクラス | D40: 各コンポーネント間の関連を説明する。 | G40: ・AI-01 | I40: ○ | J40: 0.0034722222
C41: =master!C21 -> Nレイヤーアーキテクチャ | D41: 階層(レイヤー)に役割を分けて、アプリケーションを構築することを説明する。 ▮役所の住民票異動 ・申請様式用紙：入出力 ・窓口：受付・担当を決める役割 ・住民課：具体的に業務を行う役割 ・書類棚：住民情報を保管・取得・更新する役割 | G41: ・AI-01 | I41: ○ | J41: 0.0034722222 | K41: ※アニメーション
C42: =master!C22 -> View と Controller と Service と Repository | D42: ・View（申請様式用紙） 住民票異動の申請書に必要事項を記入し、結果を受け取ります。 ※Webアプリケーションでは、ユーザーが操作する画面に相当します。 ・Controller（窓口） 窓口は申請内容を受け取り、住民票異動の申請なのか、戸籍関係の申請なのか、を判断して担当部署へ渡します。 ※Webアプリケーションでは、リクエストを受け取り適切な処理へ振り分けます。 ・Service（住民課） 住民課は、住所変更を行う、内容を確認する、必要な手続きを実施するなどの業務を行います。 ※Webアプリケーションでは、業務ルールや業務処理を担当します。 Repository（書類棚） 書類棚から住民情報を取り出したり、更新後の情報を保管したりします。 ※Webアプリケーションでは、データベースの検索・登録・更新・削除を担当します。 | G42: ・AI-01 | I42: ✕ | J42: 0.0034722222
C43: =master!C23 -> Nレイヤーアーキテクチャ | D43: 本研修におけるModelとは、「各レイヤー間でデータを受け渡す役割の総称」のこと。 ※役割や利用するレイヤーによって、Form、ViewModel、Model、Entity など異なる名称で呼ばれる。 | G43: ・AI-01 | I43: ○ | J43: 0.0020833333
C44: =master!C24 -> Webアプリケーション フレームワーク | D44: フレームワークとは、「アプリケーション開発を効率化するために、よく利用される機能や仕組みをあらかじめ提供しているソフトウェア」のこと。 Webアプリケーション開発では、 ・HTTPリクエストを受け取る ・データを埋め込んだHTMLを生成する ・データベースと連携する などの機能がフレームワークによって提供されているため、開発者は業務に必要な部分の実装に集中することができる。 開発者は、フレームワークが用意したルールや構造に従うことで、効率的にアプリケーションを開発できる。 | G44: ・AI-01 | I44: ○ | J44: 0.0034722222
C45: =master!C25 -> Java向けWebアプリケーションフレームワーク | D45: Javaで開発するWebアプリケーションフレームワークは複数あるが、Springフレームワークの一強になっている。 | G45: ・AI-01 | I45: ○ | J45: 0.00069444444
...

Sheet master
B1: AI Native-バイブコーディング
B2: 章の名称 | C2: 節の名称
B3: バイブコーディングの導入 | C3: 講義の目的
B4: Webアプリケーションとは | C4: Webアプリケーションとは
C5: Webアプリケーションの種類
C6: アプリケーションとは
C7: Web画面アプリケーション
C8: ブラウザからのリクエスト種類
B9: データベースとは | C9: データベースとは
C10: リレーショナルデータベース
C11: データベースの役割
C12: 2.1.テーブル
C13: 2.2.データ型１
C14: 2.2.データ型２
C15: 2.3.リレーション
C16: 2.4.データを結合して取得（Join）
B17: Java言語、Springフレームワークとは | C17: Webアプリケーションを作成するためのプログラミング言語
C18: Java
C19: Java言語の構成要素
C20: Webアプリケーションを構成するクラス
C21: Nレイヤーアーキテクチャ
C22: View と Controller と Service と Repository
C23: Nレイヤーアーキテクチャ
C24: Webアプリケーション フレームワーク
C25: Java向けWebアプリケーションフレームワーク
C26: Springフレームワーク
C27: Springフレームワーク：DIコンテナとは
C28: DIコンテナ：DIコンテナが部品を注入する
C29: DIコンテナ：DIコンテナによる部品と注入対象になるための目印
... C35: おすすめ書籍：『プロになるためのSpring入門』
B37: 課題1の導入 | C37: 演習課題の概要
C38: 作成物
C39: 演習課題の進め方
B40: Spring Bootプロジェクトの_x000B_準備、起動確認 | C40: 前提条件
C41: Spring Bootプロジェクトの準備
C42: （補足）Spring Bootプロジェクトの準備
C43: Spring Bootアプリケーションの起動確認
B44: ECサイト Webアプリの要件 | C44: ECサイト Webアプリの要件 – はじめに
C45: ECサイト Webアプリの要件➊ 画面
C46: ECサイト Webアプリの要件➋ 機能
...
